<?xml version="1.0" ?>
<!-- =================================================================================== -->
<!-- |    This document was autogenerated by xacro from xacro/omnihand_right.xacro     | -->
<!-- |    EDITING THIS FILE BY HAND IS NOT RECOMMENDED                                 | -->
<!-- =================================================================================== -->
<robot name="omnihand">
  <!-- joint position value -->
  <material name="black">
    <color rgba="0.0 0.0 0.0 1.0"/>
  </material>
  <material name="blue">
    <color rgba="0.0 0.0 0.8 1.0"/>
  </material>
  <material name="green">
    <color rgba="0.0 0.8 0.0 1.0"/>
  </material>
  <material name="grey">
    <color rgba="0.2 0.2 0.2 1.0"/>
  </material>
  <material name="silver">
    <color rgba="0.9137254901960784 0.9137254901960784 0.8470588235294118 1.0"/>
  </material>
  <material name="orange">
    <color rgba="1.0 0.4235294117647059 0.0392156862745098 1.0"/>
  </material>
  <material name="brown">
    <color rgba="0.8705882352941177 0.8117647058823529 0.7647058823529411 1.0"/>
  </material>
  <material name="red">
    <color rgba="0.8 0.0 0.0 1.0"/>
  </material>
  <material name="white">
    <color rgba="1.0 1.0 1.0 1.0"/>
  </material>
  <link name="base_link">
    <visual>
      <origin rpy="0.0 0.0 0.0" xyz="0.0 0.0 0.0"/>
      <geometry>
        <box size="0.001 0.001 0.001"/>
      </geometry>
    </visual>
  </link>
  <joint name="R_palm_joint" type="fixed">
    <origin rpy="0.0 0.0 0.0" xyz="0.0 0.0 0.0"/>
    <parent link="base_link"/>
    <child link="R_palm"/>
  </joint>
  <link name="R_palm">
    <visual>
      <origin rpy="0 0 0" xyz="0 0 0"/>
      <geometry>
        <mesh filename="/home/hj/Desktop/aima_moduel/omnihand_description/assets/meshes/r_palm.STL"/>
      </geometry>
      <material name="silver"/>
    </visual>
    <collision>
      <origin rpy="0 0 0" xyz="0 0 0.00725"/>
      <geometry>
        <cylinder length="0.0145" radius="0.028"/>
      </geometry>
    </collision>
    <collision>
      <origin rpy="0 0 0" xyz="0 0 0.057"/>
      <geometry>
        <box size="0.04 0.082 0.085"/>
      </geometry>
    </collision>
    <inertial>
      <origin rpy="0 0 0" xyz="0.0035098 0.0445331 -0.0066051"/>
      <mass value="0.1594"/>
      <inertia ixx="0.0001025" ixy="-3.1e-06" ixz="9.7e-07" iyy="9.973e-05" iyz="-8.3e-07" izz="0.00015087"/>
    </inertial>
  </link>
  <!-- thumb  -->
  <joint name="R_thumb_roll_joint" type="revolute">
    <origin rpy="0 0 0" xyz="0 0.018521 0.047551"/>
    <parent link="R_palm"/>
    <child link="R_thumb_roll"/>
    <axis xyz="1 0 0"/>
    <limit effort="0.419" lower="-0.17453292519943295" upper="0.8726646259971648" velocity="0.164"/>
  </joint>
  <link name="R_thumb_roll">
    <visual>
      <origin rpy="0 0 0" xyz="0 0 0"/>
      <geometry>
        <mesh filename="/home/hj/Desktop/aima_moduel/omnihand_description/assets/meshes/r_thumb_roll.STL"/>
      </geometry>
      <material name="blue"/>
    </visual>
    <inertial>
      <origin rpy="0 0 0" xyz="-0.003851 -0.000311 0.008401"/>
      <mass value="0.025"/>
      <inertia ixx="2.86e-06" ixy="0.0" ixz="3e-08" iyy="2.01e-06" iyz="5e-08" izz="3.69e-06"/>
    </inertial>
  </link>
  <joint name="R_thumb_abad_joint" type="revolute">
    <origin rpy="0 0 0" xyz="0.020801 0.004292 -0.00052506"/>
    <parent link="R_thumb_roll"/>
    <child link="R_thumb_abad"/>
    <axis xyz="0 0 1"/>
    <limit effort="0.314" lower="-1.7453292519943295" upper="0" velocity="0.164"/>
  </joint>
  <link name="R_thumb_abad">
    <visual>
      <origin rpy="0 0 0" xyz="0 0 0"/>
      <geometry>
        <mesh filename="/home/hj/Desktop/aima_moduel/omnihand_description/assets/meshes/thumb_abad.STL"/>
      </geometry>
      <material name="blue"/>
    </visual>
    <inertial>
      <origin rpy="0 0 0" xyz="-1.2e-06 0.0129928 -0.0041829"/>
      <mass value="0.0056"/>
      <inertia ixx="1.03e-06" ixy="0.0" ixz="0.0" iyy="8.8e-07" iyz="-6e-08" izz="5.2e-07"/>
    </inertial>
  </link>
  <joint name="R_thumb_mcp_joint" type="revolute">
    <origin rpy="0 0 0" xyz="0 0.0265 -0.005275"/>
    <parent link="R_thumb_abad"/>
    <child link="R_thumb_mcp"/>
    <axis xyz="1 0 0"/>
    <limit effort="1.764" lower="0" upper="0.8552113334772214" velocity="0.308"/>
  </joint>
  <link name="R_thumb_mcp">
    <visual>
      <origin rpy="0 0 0" xyz="0 0 0"/>
      <geometry>
        <mesh filename="/home/hj/Desktop/aima_moduel/omnihand_description/assets/meshes/thumb_mcp.STL"/>
      </geometry>
      <material name="brown"/>
    </visual>
    <collision>
      <origin rpy="0 0 0" xyz="0 0.0065 0.00237"/>
      <geometry>
        <box size="0.029 0.042 0.0325"/>
      </geometry>
    </collision>
    <inertial>
      <origin rpy="0 0 0" xyz="-1.83e-05 0.0225829 0.0024013"/>
      <mass value="0.0511"/>
      <inertia ixx="1.274e-05" ixy="-1e-08" ixz="0.0" iyy="4.72e-06" iyz="-2.8e-07" izz="1.121e-05"/>
    </inertial>
  </link>
  <joint name="R_thumb_pip_joint" type="revolute">
    <origin rpy="0 0 0" xyz="0 0.036231 0.0036755"/>
    <parent link="R_thumb_mcp"/>
    <child link="R_thumb_pip"/>
    <axis xyz="1 0 0"/>
    <limit effort="1.764" lower="0" upper="1.1344640137963142" velocity="0.308"/>
    <mimic joint="R_thumb_mcp_joint" multiplier="1.33" offset="0"/>
  </joint>
  <link name="R_thumb_pip">
    <visual>
      <origin rpy="0 0 0" xyz="0 0 0"/>
      <geometry>
        <mesh filename="/home/hj/Desktop/aima_moduel/omnihand_description/assets/meshes/thumb_pip.STL"/>
      </geometry>
      <material name="white"/>
    </visual>
    <collision>
      <origin rpy="-0.2 0 0" xyz="0 0.0116 -0.0032"/>
      <geometry>
        <box size="0.019 0.035 0.0225"/>
      </geometry>
    </collision>
    <inertial>
      <origin rpy="0 0 0" xyz="-1e-06 0.014461 -0.00415"/>
      <mass value="0.011"/>
      <inertia ixx="1.34e-06" ixy="0.0" ixz="0.0" iyy="7.9e-07" iyz="7e-08" izz="1.31e-06"/>
    </inertial>
  </link>
  <joint name="R_thumb_dip_joint" type="revolute">
    <origin rpy="0 0 0" xyz="0 0.026468 -0.0073106"/>
    <parent link="R_thumb_pip"/>
    <child link="R_thumb_dip"/>
    <axis xyz="1 0 0"/>
    <limit effort="1.764" lower="0" upper="1.1344640137963142" velocity="0.308"/>
    <mimic joint="R_thumb_mcp_joint" multiplier="1.3" offset="0"/>
  </joint>
  <link name="R_thumb_dip">
    <visual>
      <origin rpy="0 0 0" xyz="0 0 0"/>
      <geometry>
        <mesh filename="/home/hj/Desktop/aima_moduel/omnihand_description/assets/meshes/thumb_dip.STL"/>
      </geometry>
      <material name="white"/>
    </visual>
    <collision>
      <origin rpy="-1.8 0 0" xyz="0 0.0134 -0.0026"/>
      <geometry>
        <cylinder length="0.023" radius="0.011"/>
      </geometry>
    </collision>
    <inertial>
      <origin rpy="0 0 0" xyz="-3e-06 0.010392 -0.001614"/>
      <mass value="0.007"/>
      <inertia ixx="5.2e-07" ixy="0.0" ixz="0.0" iyy="3.3e-07" iyz="-1.6e-07" izz="4.4e-07"/>
    </inertial>
  </link>
  <joint name="R_thumb_tip_joint" type="fixed">
    <origin rpy="0 0 0" xyz="0 0.02392 -0.01158"/>
    <parent link="R_thumb_dip"/>
    <child link="R_thumb_tip"/>
  </joint>
  <link name="R_thumb_tip">
    <visual>
      <origin rpy="0 0 0" xyz="0 0 0"/>
      <geometry>
        <sphere radius="1e-3"/>
      </geometry>
      <material name="white"/>
    </visual>
  </link>
  <!-- finger  -->
  <joint name="R_index_abad_joint" type="revolute">
    <origin rpy="0 0 0" xyz="0 0.02695 0.094548"/>
    <parent link="R_palm"/>
    <child link="R_index_abad"/>
    <axis xyz="1 0 0"/>
    <limit effort="1.863" lower="-0.20943951023931953" upper="0" velocity="0.164"/>
  </joint>
  <link name="R_index_abad">
    <visual>
      <origin rpy="0 0 0" xyz="0 0 0"/>
      <geometry>
        <mesh filename="/home/hj/Desktop/aima_moduel/omnihand_description/assets/meshes/finger_abad.STL"/>
      </geometry>
      <material name="green"/>
    </visual>
    <inertial>
      <origin rpy="0 0 0" xyz="-0.0018959 -9.8e-06 0.0066855"/>
      <mass value="0.04"/>
      <inertia ixx="7.37e-06" ixy="0.0" ixz="-1.4e-07" iyy="8.82e-06" iyz="0.0" izz="2.65e-06"/>
    </inertial>
  </link>
  
        y 
  <joint name="R_index_pip_joint" type="revolute">
    <origin rpy="0 0 0" xyz="0.00048163 0 0.017575"/>
    <parent link="R_index_abad"/>
    <child link="R_index_pip"/>
    <axis xyz="0 1 0"/>
    <limit effort="1.764" lower="0" upper="1.5707963267948966" velocity="0.308"/>
  </joint>
  <link name="R_index_pip">
    <visual>
      <origin rpy="0 0 0" xyz="0 0 0"/>
      <geometry>
        <mesh filename="/home/hj/Desktop/aima_moduel/omnihand_description/assets/meshes/finger_pip.STL"/>
      </geometry>
      <material name="brown"/>
    </visual>
    <collision>
      <origin rpy="0 0 0" xyz="0 0 0.014"/>
      <geometry>
        <cylinder length="0.044" radius="0.01"/>
      </geometry>
    </collision>
    <inertial>
      <origin rpy="0 0 0" xyz="-0.002884 1.5e-06 0.019997"/>
      <mass value="0.004"/>
      <inertia ixx="7e-07" ixy="0.0" ixz="1e-08" iyy="6.8e-07" iyz="0.0" izz="2.6e-07"/>
    </inertial>
  </link>
  <joint name="R_index_dip_joint" type="revolute">
    <origin rpy="0 0 0" xyz=" -0.0015  0 0.036"/>
    <parent link="R_index_pip"/>
    <child link="R_index_dip"/>
    <axis xyz="0 1 0"/>
    <limit effort="1.764" lower="0" upper="1.8325957145940461" velocity="0.308"/>
    <mimic joint="R_index_pip_joint" multiplier="1.097" offset="0"/>
  </joint>
  <link name="R_index_dip">
    <visual>
      <origin rpy="0 0 0" xyz="0 0 0"/>
      <geometry>
        <mesh filename="/home/hj/Desktop/aima_moduel/omnihand_description/assets/meshes/finger_dip.STL"/>
      </geometry>
      <material name="orange"/>
    </visual>
    <collision>
      <origin rpy="0 0 0" xyz="0 0 0.018"/>
      <geometry>
        <cylinder length="0.034" radius="0.007"/>
      </geometry>
    </collision>
    <inertial>
      <origin rpy="0 0 0" xyz="0.000618 0.0 0.019239"/>
      <mass value="0.003"/>
      <inertia ixx="4e-07" ixy="0.0" ixz="0.0" iyy="4e-07" iyz="0.0" izz="1.2e-07"/>
    </inertial>
  </link>
  <joint name="R_index_tip_joint" type="fixed">
    <origin rpy="0 0 0" xyz="-0.0011 0 0.03612"/>
    <parent link="R_index_dip"/>
    <child link="R_index_tip"/>
  </joint>
  <link name="R_index_tip">
    <visual>
      <origin rpy="0 0 0" xyz="0 0 0"/>
      <geometry>
        <sphere radius="1e-3"/>
      </geometry>
      <material name="white"/>
    </visual>
  </link>
  <joint name="R_middle_abad_joint" type="fixed">
    <origin rpy="0 0 0" xyz="-0.0025 0.00795 0.096548"/>
    <parent link="R_palm"/>
    <child link="R_middle_abad"/>
  </joint>
  <link name="R_middle_abad">
    <visual>
      <origin rpy="0 0 0" xyz="0 0 0"/>
      <geometry>
        <mesh filename="/home/hj/Desktop/aima_moduel/omnihand_description/assets/meshes/finger_abad.STL"/>
      </geometry>
      <material name="green"/>
    </visual>
    <inertial>
      <origin rpy="0 0 0" xyz="-0.0018959 -9.8e-06 0.0066855"/>
      <mass value="0.04"/>
      <inertia ixx="7.37e-06" ixy="0.0" ixz="-1.4e-07" iyy="8.82e-06" iyz="0.0" izz="2.65e-06"/>
    </inertial>
  </link>
  
        y 
  <joint name="R_middle_pip_joint" type="revolute">
    <origin rpy="0 0 0" xyz="0.00048163 0 0.017575"/>
    <parent link="R_middle_abad"/>
    <child link="R_middle_pip"/>
    <axis xyz="0 1 0"/>
    <limit effort="1.764" lower="0" upper="1.5707963267948966" velocity="0.308"/>
  </joint>
  <link name="R_middle_pip">
    <visual>
      <origin rpy="0 0 0" xyz="0 0 0"/>
      <geometry>
        <mesh filename="/home/hj/Desktop/aima_moduel/omnihand_description/assets/meshes/finger_pip.STL"/>
      </geometry>
      <material name="brown"/>
    </visual>
    <collision>
      <origin rpy="0 0 0" xyz="0 0 0.014"/>
      <geometry>
        <cylinder length="0.044" radius="0.01"/>
      </geometry>
    </collision>
    <inertial>
      <origin rpy="0 0 0" xyz="-0.002884 1.5e-06 0.019997"/>
      <mass value="0.004"/>
      <inertia ixx="7e-07" ixy="0.0" ixz="1e-08" iyy="6.8e-07" iyz="0.0" izz="2.6e-07"/>
    </inertial>
  </link>
  <joint name="R_middle_dip_joint" type="revolute">
    <origin rpy="0 0 0" xyz=" -0.0015  0 0.036"/>
    <parent link="R_middle_pip"/>
    <child link="R_middle_dip"/>
    <axis xyz="0 1 0"/>
    <limit effort="1.764" lower="0" upper="1.8325957145940461" velocity="0.308"/>
    <mimic joint="R_middle_pip_joint" multiplier="1.097" offset="0"/>
  </joint>
  <link name="R_middle_dip">
    <visual>
      <origin rpy="0 0 0" xyz="0 0 0"/>
      <geometry>
        <mesh filename="/home/hj/Desktop/aima_moduel/omnihand_description/assets/meshes/finger_dip.STL"/>
      </geometry>
      <material name="orange"/>
    </visual>
    <collision>
      <origin rpy="0 0 0" xyz="0 0 0.018"/>
      <geometry>
        <cylinder length="0.034" radius="0.007"/>
      </geometry>
    </collision>
    <inertial>
      <origin rpy="0 0 0" xyz="0.000618 0.0 0.019239"/>
      <mass value="0.003"/>
      <inertia ixx="4e-07" ixy="0.0" ixz="0.0" iyy="4e-07" iyz="0.0" izz="1.2e-07"/>
    </inertial>
  </link>
  <joint name="R_middle_tip_joint" type="fixed">
    <origin rpy="0 0 0" xyz="-0.0011 0 0.03612"/>
    <parent link="R_middle_dip"/>
    <child link="R_middle_tip"/>
  </joint>
  <link name="R_middle_tip">
    <visual>
      <origin rpy="0 0 0" xyz="0 0 0"/>
      <geometry>
        <sphere radius="1e-3"/>
      </geometry>
      <material name="white"/>
    </visual>
  </link>
  <joint name="R_ring_abad_joint" type="revolute">
    <origin rpy="0 0 0" xyz="-0.00151 -0.01105 0.094548"/>
    <parent link="R_palm"/>
    <child link="R_ring_abad"/>
    <axis xyz="1 0 0"/>
    <limit effort="2.766" lower="0" upper="0.17453292519943295" velocity="0.164"/>
  </joint>
  <link name="R_ring_abad">
    <visual>
      <origin rpy="0 0 0" xyz="0 0 0"/>
      <geometry>
        <mesh filename="/home/hj/Desktop/aima_moduel/omnihand_description/assets/meshes/finger_abad.STL"/>
      </geometry>
      <material name="green"/>
    </visual>
    <inertial>
      <origin rpy="0 0 0" xyz="-0.0018959 -9.8e-06 0.0066855"/>
      <mass value="0.04"/>
      <inertia ixx="7.37e-06" ixy="0.0" ixz="-1.4e-07" iyy="8.82e-06" iyz="0.0" izz="2.65e-06"/>
    </inertial>
  </link>
  
        y 
  <joint name="R_ring_pip_joint" type="revolute">
    <origin rpy="0 0 0" xyz="0.00048163 0 0.017575"/>
    <parent link="R_ring_abad"/>
    <child link="R_ring_pip"/>
    <axis xyz="0 1 0"/>
    <limit effort="1.764" lower="0" upper="1.5707963267948966" velocity="0.308"/>
  </joint>
  <link name="R_ring_pip">
    <visual>
      <origin rpy="0 0 0" xyz="0 0 0"/>
      <geometry>
        <mesh filename="/home/hj/Desktop/aima_moduel/omnihand_description/assets/meshes/finger_pip.STL"/>
      </geometry>
      <material name="brown"/>
    </visual>
    <collision>
      <origin rpy="0 0 0" xyz="0 0 0.014"/>
      <geometry>
        <cylinder length="0.044" radius="0.01"/>
      </geometry>
    </collision>
    <inertial>
      <origin rpy="0 0 0" xyz="-0.002884 1.5e-06 0.019997"/>
      <mass value="0.004"/>
      <inertia ixx="7e-07" ixy="0.0" ixz="1e-08" iyy="6.8e-07" iyz="0.0" izz="2.6e-07"/>
    </inertial>
  </link>
  <joint name="R_ring_dip_joint" type="revolute">
    <origin rpy="0 0 0" xyz=" -0.0015  0 0.036"/>
    <parent link="R_ring_pip"/>
    <child link="R_ring_dip"/>
    <axis xyz="0 1 0"/>
    <limit effort="1.764" lower="0" upper="1.8325957145940461" velocity="0.308"/>
    <mimic joint="R_ring_pip_joint" multiplier="1.097" offset="0"/>
  </joint>
  <link name="R_ring_dip">
    <visual>
      <origin rpy="0 0 0" xyz="0 0 0"/>
      <geometry>
        <mesh filename="/home/hj/Desktop/aima_moduel/omnihand_description/assets/meshes/finger_dip.STL"/>
      </geometry>
      <material name="orange"/>
    </visual>
    <collision>
      <origin rpy="0 0 0" xyz="0 0 0.018"/>
      <geometry>
        <cylinder length="0.034" radius="0.007"/>
      </geometry>
    </collision>
    <inertial>
      <origin rpy="0 0 0" xyz="0.000618 0.0 0.019239"/>
      <mass value="0.003"/>
      <inertia ixx="4e-07" ixy="0.0" ixz="0.0" iyy="4e-07" iyz="0.0" izz="1.2e-07"/>
    </inertial>
  </link>
  <joint name="R_ring_tip_joint" type="fixed">
    <origin rpy="0 0 0" xyz="-0.0011 0 0.03612"/>
    <parent link="R_ring_dip"/>
    <child link="R_ring_tip"/>
  </joint>
  <link name="R_ring_tip">
    <visual>
      <origin rpy="0 0 0" xyz="0 0 0"/>
      <geometry>
        <sphere radius="1e-3"/>
      </geometry>
      <material name="white"/>
    </visual>
  </link>
  <joint name="R_pinky_abad_joint" type="revolute">
    <origin rpy="0 0 0" xyz="0 -0.03005 0.089548"/>
    <parent link="R_palm"/>
    <child link="R_pinky_abad"/>
    <axis xyz="1 0 0"/>
    <limit effort="3.393" lower="0" upper="0.17453292519943295" velocity="0.164"/>
  </joint>
  <link name="R_pinky_abad">
    <visual>
      <origin rpy="0 0 0" xyz="0 0 0"/>
      <geometry>
        <mesh filename="/home/hj/Desktop/aima_moduel/omnihand_description/assets/meshes/finger_abad.STL"/>
      </geometry>
      <material name="green"/>
    </visual>
    <inertial>
      <origin rpy="0 0 0" xyz="-0.0018959 -9.8e-06 0.0066855"/>
      <mass value="0.04"/>
      <inertia ixx="7.37e-06" ixy="0.0" ixz="-1.4e-07" iyy="8.82e-06" iyz="0.0" izz="2.65e-06"/>
    </inertial>
  </link>
  
        y 
  <joint name="R_pinky_pip_joint" type="revolute">
    <origin rpy="0 0 0" xyz="0.00048163 0 0.017575"/>
    <parent link="R_pinky_abad"/>
    <child link="R_pinky_pip"/>
    <axis xyz="0 1 0"/>
    <limit effort="1.764" lower="0" upper="1.5707963267948966" velocity="0.308"/>
  </joint>
  <link name="R_pinky_pip">
    <visual>
      <origin rpy="0 0 0" xyz="0 0 0"/>
      <geometry>
        <mesh filename="/home/hj/Desktop/aima_moduel/omnihand_description/assets/meshes/finger_pip.STL"/>
      </geometry>
      <material name="brown"/>
    </visual>
    <collision>
      <origin rpy="0 0 0" xyz="0 0 0.014"/>
      <geometry>
        <cylinder length="0.044" radius="0.01"/>
      </geometry>
    </collision>
    <inertial>
      <origin rpy="0 0 0" xyz="-0.002884 1.5e-06 0.019997"/>
      <mass value="0.004"/>
      <inertia ixx="7e-07" ixy="0.0" ixz="1e-08" iyy="6.8e-07" iyz="0.0" izz="2.6e-07"/>
    </inertial>
  </link>
  <joint name="R_pinky_dip_joint" type="revolute">
    <origin rpy="0 0 0" xyz=" -0.0015  0 0.036"/>
    <parent link="R_pinky_pip"/>
    <child link="R_pinky_dip"/>
    <axis xyz="0 1 0"/>
    <limit effort="1.764" lower="0" upper="1.8325957145940461" velocity="0.308"/>
    <mimic joint="R_pinky_pip_joint" multiplier="1.097" offset="0"/>
  </joint>
  <link name="R_pinky_dip">
    <visual>
      <origin rpy="0 0 0" xyz="0 0 0"/>
      <geometry>
        <mesh filename="/home/hj/Desktop/aima_moduel/omnihand_description/assets/meshes/finger_dip.STL"/>
      </geometry>
      <material name="orange"/>
    </visual>
    <collision>
      <origin rpy="0 0 0" xyz="0 0 0.018"/>
      <geometry>
        <cylinder length="0.034" radius="0.007"/>
      </geometry>
    </collision>
    <inertial>
      <origin rpy="0 0 0" xyz="0.000618 0.0 0.019239"/>
      <mass value="0.003"/>
      <inertia ixx="4e-07" ixy="0.0" ixz="0.0" iyy="4e-07" iyz="0.0" izz="1.2e-07"/>
    </inertial>
  </link>
  <joint name="R_pinky_tip_joint" type="fixed">
    <origin rpy="0 0 0" xyz="-0.0011 0 0.03612"/>
    <parent link="R_pinky_dip"/>
    <child link="R_pinky_tip"/>
  </joint>
  <link name="R_pinky_tip">
    <visual>
      <origin rpy="0 0 0" xyz="0 0 0"/>
      <geometry>
        <sphere radius="1e-3"/>
      </geometry>
      <material name="white"/>
    </visual>
  </link>
</robot>
